Workbook
Name \C: #REF!
Name \P: #REF!
Name \Q: #REF!
Name \S: #REF!
Name \X: #REF!
Name _aud2: #REF!
Name _cov1: #REF!
Name _cov2: #REF!
Name _cov3: #REF!
Name _cov4: #REF!
Name _DAT1: #REF!
Name _DAT2: #REF!
Name _DAT3: #REF!
Name _DAT4: #REF!
Name _DAT5: #REF!
Name _DAT6: #REF!
Name _DAT7: #REF!
Name _DAT8: #REF!
Name _DCF2: #REF!
Name _iia2: #REF!
Name _op2: #REF!
Name _rev2: #REF!
Name _SYN1: #REF!
Name _SYN2: #REF!
Name _UST10: #REF!
Name a: #REF!
Name A.IndexPos: #N/A
Name A.NewPricePaste: #N/A
Name A.NewPriceRow: #N/A
Name A.VolPos: #N/A
Name accrued: #REF!
Name ACQ: #REF!
Name acqnumber: #REF!
Name acqrevgrowth: #REF!
Name actual_start_year: 1993
Name Adj: #REF!
Name amort: #REF!
Name Annualization_Factor: 69.03/54.876539
Name anumber: #REF!
Name ardays: #REF!
Name arevgrowth: #REF!
Name asfa: 'Assumption 2 Documentation'!asfa
Name asfa: 'Assumptions 1 Documentation'!asfa
Name asfa: GDP!asfa
Name asfa: [0]!asfa
Name asfasfas: 'Assumption 2 Documentation'!asfasfas
Name asfasfas: 'Assumptions 1 Documentation'!asfasfas
Name asfasfas: GDP!asfasfas
Name asfasfas: [0]!asfasfas
Name asfasfsa: 'Assumption 2 Documentation'!asfasfsa
Name asfasfsa: 'Assumptions 1 Documentation'!asfasfsa
Name asfasfsa: GDP!asfasfsa
Name asfasfsa: [0]!asfasfsa
Name asfdasfs: 'Assumption 2 Documentation'!asfdasfs
Name asfdasfs: 'Assumptions 1 Documentation'!asfdasfs
Name asfdasfs: GDP!asfdasfs
Name asfdasfs: [0]!asfdasfs
Name asfsaf: 'Assumption 2 Documentation'!asfsaf
Name asfsaf: 'Assumptions 1 Documentation'!asfsaf
Name asfsaf: GDP!asfsaf

Sheet Cover
G6: Planet Fitness, Inc.
G7: Valuation, LBOs, M&A, and IPOs
G12: DCF Analysis
C20: Team #5
C21: Henrique Menezes, Aoi Morinaga, Cristiano Carta, Soumya Tiwari, Ivan Pava, Beyza Cengelkoy

Sheet DCF
B1: =Cover!G6 -> Planet Fitness, Inc.
B2: Discounted Cash Flow Analysis
B3: ($ in thousands, fiscal year ending December 31) | M3: =B4 -> Operating Scenario | O3: =+CHOOSE(D4,'AS1'!B8,'AS1'!B9,'AS1'!B10,'AS1'!#REF!,'AS1'!#REF!) -> Base
B4: Operating Scenario | D4: 1
B5: Mid-Year Convention | D5: Y | E5: Historical Period | H5: CAGR | J5: Projection Period | O5: CAGR
E6: =+F6-1 -> 2021 | F6: =+G6-1 -> 2022 | G6: =+I6-1 -> 2023 | H6: ('21 - '23) | I6: 2024 | J6: =+I6+1 -> 2025 | K6: =+J6+1 -> 2026 | L6: =+K6+1 -> 2027 | M6: =+L6+1 -> 2028 | N6: =+M6+1 -> 2029 | O6: ('24 - '29)
B7: Sales | E7: 587023 | F7: 936772 | G7: 1071326 | H7: =+IF(ISERROR((G7/E7)^(1/($G$6-$E$6))-1),"-",(G7/E7)^(1/($G$6-$E$6))-1) -> 0.3509313 | I7: 1181654 | J7: =I7*(1+J59) -> 1299819.4 | K7: =J7*(1+K59) -> 1423302.2 | L7: =K7*(1+L59) -> 1551399.4 | M7: =L7*(1+M59) -> 1687922.6 | N7: =M7*(1+N59) -> 1836459.8 | O7: =+IF(ISERROR((N7/I7)^(1/($N$6-$I$6))-1),"-",(N7/I7)^(1/($N$6-$I$6))-1) -> 0.092190057
B8: % growth | E8: NA | F8: =+IF(ISERROR(F7/E7-1),0,F7/E7-1) -> 0.59580119 | G8: =+IF(ISERROR(G7/F7-1),0,G7/F7-1) -> 0.1436358 | I8: =+IF(ISERROR(I7/G7-1),0,I7/G7-1) -> 0.10298266 | J8: =+IF(ISERROR(J7/I7-1),0,J7/I7-1) -> 0.1 | K8: =+IF(ISERROR(K7/J7-1),0,K7/J7-1) -> 0.095 | L8: =+IF(ISERROR(L7/K7-1),0,L7/K7-1) -> 0.09 | M8: =+IF(ISERROR(M7/L7-1),0,M7/L7-1) -> 0.088 | N8: =+IF(ISERROR(N7/M7-1),0,N7/M7-1) -> 0.088
B9: Cost of Goods Sold | E9: 170158 | F9: 285538 | G9: 323714 | I9: 369516 | J9: =J7*J60 -> 409443.11 | K9: =K7*K60 -> 448340.21 | L9: =L7*L60 -> 488690.83 | M9: =M7*M60 -> 531695.62 | N9: =N7*N60 -> 578484.83
B10: Gross Profit | E10: =+E7-E9 -> 416865 | F10: =+F7-F9 -> 651234 | G10: =+G7-G9 -> 747612 | H10: =+IF(ISERROR((G10/E10)^(1/($G$6-$E$6))-1),"-",(G10/E10)^(1/($G$6-$E$6))-1) -> 0.3391845 | I10: =+I7-I9 -> 812138 | J10: =+J7-J9 -> 890376.29 | K10: =+K7-K9 -> 974962.04 | L10: =+L7-L9 -> 1062708.6 | M10: =+M7-M9 -> 1156227 | N10: =+N7-N9 -> 1257975 | O10: =+IF(ISERROR((N10/I10)^(1/($N$6-$I$6))-1),"-",(N10/I10)^(1/($N$6-$I$6))-1) -> 0.091461529
B11: % margin | E11: =+IF(ISERROR(E10/E7),0,E10/E7) -> 0.71013402 | F11: =+IF(ISERROR(F10/F7),0,F10/F7) -> 0.69518944 | G11: =+IF(ISERROR(G10/G7),0,G10/G7) -> 0.69783801 | I11: =+IF(ISERROR(I10/I7),0,I10/I7) -> 0.68728917 | J11: =+IF(ISERROR(J10/J7),0,J10/J7) -> 0.685 | K11: =+IF(ISERROR(K10/K7),0,K10/K7) -> 0.685 | L11: =+IF(ISERROR(L10/L7),0,L10/L7) -> 0.685 | M11: =+IF(ISERROR(M10/M7),0,M10/M7) -> 0.685 | N11: =+IF(ISERROR(N10/N7),0,N10/N7) -> 0.685
B12: Selling, General & Administrative | E12: 94540 | F12: 114853 | G12: 124930 | I12: 129146 | J12: =J7*J61 -> 129981.94 | K12: =K7*K61 -> 142330.22 | L12: =L7*L61 -> 155139.94 | M12: =M7*M61 -> 168792.26 | N12: =N7*N61 -> 183645.98
B13: EBITDA | E13: =E10-E12 -> 322325 | F13: =F10-F12 -> 536381 | G13: =G10-G12 -> 622682 | H13: =+IF(ISERROR((G13/E13)^(1/($G$6-$E$6))-1),"-",(G13/E13)^(1/($G$6-$E$6))-1) -> 0.38990834 | I13: =I10-I12 -> 682992 | J13: =J10-J12 -> 760394.35 | K13: =K10-K12 -> 832631.81 | L13: =L10-L12 -> 907568.68 | M13: =M10-M12 -> 987434.72 | N13: =N10-N12 -> 1074329 | O13: =+IF(ISERROR((N13/I13)^(1/($N$6-$I$6))-1),"-",(N13/I13)^(1/($N$6-$I$6))-1) -> 0.094824064
B14: % margin | E14: =+IF(ISERROR(E13/E7),0,E13/E7) -> 0.54908411 | F14: =+IF(ISERROR(F13/F7),0,F13/F7) -> 0.57258436 | G14: =+IF(ISERROR(G13/G7),0,G13/G7) -> 0.58122551 | I14: =+IF(ISERROR(I13/I7),0,I13/I7) -> 0.5779966 | J14: =+IF(ISERROR(J13/J7),0,J13/J7) -> 0.585 | K14: =+IF(ISERROR(K13/K7),0,K13/K7) -> 0.585 | L14: =+IF(ISERROR(L13/L7),0,L13/L7) -> 0.585 | M14: =+IF(ISERROR(M13/M7),0,M13/M7) -> 0.585 | N14: =+IF(ISERROR(N13/N7),0,N13/N7) -> 0.585
B15: Depreciation & Amortization | E15: 62800 | F15: 124022 | G15: 149413 | I15: 160346 | J15: =J7*J62 -> 176342.17 | K15: =K7*K62 -> 193094.67 | L15: =L7*L62 -> 210473.19 | M15: =M7*M62 -> 228994.83 | N15: =N7*N62 -> 249146.38
B16: EBIT | E16: =+E13-E15 -> 259525 | F16: =+F13-F15 -> 412359 | G16: =+G13-G15 -> 473269 | H16: =+IF(ISERROR((G16/E16)^(1/($G$6-$E$6))-1),"-",(G16/E16)^(1/($G$6-$E$6))-1) -> 0.35040622 | I16: =+I13-I15 -> 522646 | J16: =+J13-J15 -> 584052.18 | K16: =+K13-K15 -> 639537.14 | L16: =+L13-L15 -> 697095.48 | M16: =+M13-M15 -> 758439.89 | N16: =+N13-N15 -> 825182.6 | O16: =+IF(ISERROR((N16/I16)^(1/($N$6-$I$6))-1),"-",(N16/I16)^(1/($N$6-$I$6))-1) -> 0.09564153
B17: % margin | E17: =+IF(ISERROR(E16/E7),0,E16/E7) -> 0.44210363 | F17: =+IF(ISERROR(F16/F7),0,F16/F7) -> 0.44019142 | G17: =+IF(ISERROR(G16/G7),0,G16/G7) -> 0.44176002 | I17: =+IF(ISERROR(I16/I7),0,I16/I7) -> 0.44230037 | J17: =+IF(ISERROR(J16/J7),0,J16/J7) -> 0.44933333 | K17: =+IF(ISERROR(K16/K7),0,K16/K7) -> 0.44933333 | L17: =+IF(ISERROR(L16/L7),0,L16/L7) -> 0.44933333 | M17: =+IF(ISERROR(M16/M7),0,M16/M7) -> 0.44933333 | N17: =+IF(ISERROR(N16/N7),0,N16/N7) -> 0.44933333
B18: Taxes | E18: =32%*E16 -> 83048 | F18: =32%*F16 -> 131954.88 | G18: =32%*G16 -> 151446.08 | I18: =+I16*I64 -> 144772.94 | J18: =+J16*J64 -> 161782.45 | K18: =+K16*K64 -> 177151.79 | L18: =+L16*L64 -> 193095.45 | M18: =+M16*M64 -> 210087.85 | N18: =+N16*N64 -> 228575.58
B19: EBIAT | E19: =+E16-E18 -> 176477 | F19: =+F16-F18 -> 280404.12 | G19: =+G16-G18 -> 321822.92 | H19: =+IF(ISERROR((G19/E19)^(1/($G$6-$E$6))-1),"-",(G19/E19)^(1/($G$6-$E$6))-1) -> 0.35040622 | I19: =+I16-I18 -> 377873.06 | J19: =+J16-J18 -> 422269.73 | K19: =+K16-K18 -> 462385.35 | L19: =+L16-L18 -> 504000.03 | M19: =+M16-M18 -> 548352.04 | N19: =+N16-N18 -> 596607.02 | O19: =+IF(ISERROR((N19/I19)^(1/($N$6-$I$6))-1),"-",(N19/I19)^(1/($N$6-$I$6))-1) -> 0.09564153
B21: Plus: Depreciation & Amortization | E21: =E15 -> 62800 | F21: =F15 -> 124022 | G21: =G15 -> 149413 | I21: =I15 -> 160346 | J21: =J15 -> 176342.17 | K21: =K15 -> 193094.67 | L21: =L15 -> 210473.19 | M21: =M15 -> 228994.83 | N21: =N15 -> 249146.38
B22: Less: Capital Expenditures | E22: -54074 | F22: -100057 | G22: -135986 | I22: -155061 | J22: =-(J7*J63) -> -152544.06 | K22: =-(K7*K63) -> -157543.87 | L22: =-(L7*L63) -> -162543.67 | M22: =-(M7*M63) -> -167543.48 | N22: =-(N7*N63) -> -172543.28
B23: Less: Inc./(Dec.) in Net Working Capital | E23: 36143 | F23: -21154 | G23: 6877 | I23: -19628 | J23: =NWC!G25 -> 35330.367 | K23: =NWC!H25 -> 6922.4948 | L23: =NWC!I25 -> 7181.1775 | M23: =NWC!J25 -> 7653.5394 | N23: =NWC!K25 -> 8327.0509
B25: Unlevered Free Cash Flow | J25: =+J19+SUM(J21:J23) -> 481398.2 | K25: =+K19+SUM(K21:K23) -> 504858.65 | L25: =+L19+SUM(L21:L23) -> 559110.73 | M25: =+M19+SUM(M21:M23) -> 617456.93 | N25: =+N19+SUM(N21:N23) -> 681537.16
B26: WACC | E26: =WACC!D26 -> 0.090397061
B27: Discount Period | J27: =IF($D$5="Y",J6-$I$6-0.5,J6-$I$6) -> 0.5 | K27: =IF($D$5="Y",K6-$I$6-0.5,K6-$I$6) -> 1.5 | L27: =IF($D$5="Y",L6-$I$6-0.5,L6-$I$6) -> 2.5 | M27: =IF($D$5="Y",M6-$I$6-0.5,M6-$I$6) -> 3.5 | N27: =IF($D$5="Y",N6-$I$6-0.5,N6-$I$6) -> 4.5
B28: Discount Factor | J28: =1/((1+$E$26)^(J27)) -> 0.95765188 | K28: =1/((1+$E$26)^(K27)) -> 0.87825977 | L28: =1/((1+$E$26)^(L27)) -> 0.80544951 | M28: =1/((1+$E$26)^(M27)) -> 0.73867542 | N28: =1/((1+$E$26)^(N27)) -> 0.6774371
B29: Present Value of Free Cash Flow | J29: =+J25*J28 -> 461011.89 | K29: =+K25*K28 -> 443397.05 | L29: =+L25*L28 -> 450335.46 | M29: =+M25*M28 -> 456100.26 | N29: =+N25*N28 -> 461698.56
B32: Enterprise Value | G32: Implied Equity Value and Share Price | L32: Implied Perpetuity Growth Rate
B33: Cumulative Present Value of FCF | E33: =+SUM(J29:N29) -> 2272543.2 | G33: Enterprise Value | J33: =+E43 -> 9583755.8 | L33: ="Terminal Year Free Cash Flow ("&N6&"E)" -> Terminal Year Free Cash Flow (2029E) | O33: =+N25 -> 681537.16
G34: Less: Total Debt | J34: ='WACC Documentation'!D10 -> 2575853 | L34: WACC | O34: =+E26 -> 0.090397061
B35: Terminal Value | G35: Less: Preferred Stock | J35: 0 | L35: =+B35 -> Terminal Value | O35: =+E38 -> 11269711
B36: ="Terminal Year EBITDA ("&N6&"E)" -> Terminal Year EBITDA (2029E) | E36: =+N13 -> 1074329 | G36: Less: Noncontrolling Interest | J36: 7
B37: Exit Multiple | E37: 10.49 | G37: Plus: Cash and Cash Equivalents | J37: 293150 | L37: Implied Perpetuity Growth Rate | O37: =+IF(ISERROR(IF(D5="Y",((E38*E26)-N25*(1+E26)^0.5)/(E38+N25*(1+E26)^0.5),((O35*O34)-O33)/(O35+O33))),"- %",IF(D5="Y",((E38*E26)-N25*(1+E26)^0.5)/(E38+N25*(1+E26)^0.5),((O35*O34)-O33)/(O35+O33))) -> 0.025629211
B38: Terminal Value | E38: =+E36*E37 -> 11269711
B39: Discount Factor | E39: =1/((1+$E$26)^(N6-I6)) -> 0.64874891 | G39: Implied Equity Value | J39: =J33-J34-J35-J36+J37 -> 7301045.8 | L39: Implied EV/EBITDA
B40: Present Value of Terminal Value | E40: =+E38*E39 -> 7311212.6 | L40: =+G33 -> Enterprise Value | O40: =E43 -> 9583755.8
B41: % of Enterprise Value | E41: =+IF(ISERROR(E40/E43),"- %",E40/E43) -> 0.76287551 | G41: Fully Diluted Shares Outstanding | J41: 82980 | L41: LTM EBITDA | O41: 487710
B43: Enterprise Value | E43: =+E40+E33 -> 9583755.8 | G43: Implied Share Price | J43: =+IF(ISERROR(J39/J41),"NA",J39/J41) -> 87.985609 | L43: Implied EV/EBITDA | O43: =O40/O41 -> 19.650522
C46: Enterprise Value | J46: Implied Perpetuity Growth Rate
D47: Exit Multiple | K47: Exit Multiple
...

Sheet NWC
B1: =Cover!G6 -> Planet Fitness, Inc.
B2: Working Capital Projections
B3: ($ in thousands, fiscal year ending december 31)
C5: Historical Period | G5: Projection Period
C6: =+DCF!E6 -> 2021 | D6: =+DCF!F6 -> 2022 | E6: =+DCF!G6 -> 2023 | F6: =+DCF!I6 -> 2024 | G6: =+DCF!J6 -> 2025 | H6: =+DCF!K6 -> 2026 | I6: =+DCF!L6 -> 2027 | J6: =+DCF!M6 -> 2028 | K6: =+DCF!N6 -> 2029
B7: Sales | C7: =+DCF!E7 -> 587023 | D7: =+DCF!F7 -> 936772 | E7: =+DCF!G7 -> 1071326 | F7: =+DCF!I7 -> 1181654 | G7: =+DCF!J7 -> 1299819.4 | H7: =+DCF!K7 -> 1423302.2 | I7: =+DCF!L7 -> 1551399.4 | J7: =+DCF!M7 -> 1687922.6 | K7: =+DCF!N7 -> 1836459.8
B8: Cost of Goods Sold | C8: =+DCF!E9 -> 170158 | D8: =+DCF!F9 -> 285538 | E8: =+DCF!G9 -> 323714 | F8: =+DCF!I9 -> 369516 | G8: =+DCF!J9 -> 409443.11 | H8: =+DCF!K9 -> 448340.21 | I8: =+DCF!L9 -> 488690.83 | J8: =+DCF!M9 -> 531695.62 | K8: =+DCF!N9 -> 578484.83
B9: Just Operating | C9: 15137 | D9: 5081 | E9: 10379 | F9: 1326
B10: Current Assets
B11: Accounts Receivable | C11: 27257 | D11: 46242 | E11: 41890 | F11: 77145 | G11: =+G7/365*G29 -> 66615.965 | H11: =+H7/365*H29 -> 72944.482 | I11: =+I7/365*I29 -> 79509.485 | J11: =+J7/365*J29 -> 86506.32 | K11: =+K7/365*K29 -> 94118.876
B12: Inventories | C12: 1155 | D12: 5266 | E12: 4677 | F12: 6146 | G12: =+G8/365*G30 -> 0 | H12: =+H8/365*H30 -> 0 | I12: =+I8/365*I30 -> 0 | J12: =+J8/365*J30 -> 0 | K12: =+K8/365*K30 -> 0
B13: Prepaid Expenses and Other | C13: 12869 | D13: 11078 | E13: 13842 | F13: 21499 | G13: =+G7*G31 -> 18600.416 | H13: =+H7*H31 -> 20367.455 | I13: =+I7*I31 -> 22200.526 | J13: =+J7*J31 -> 24154.172 | K13: =+K7*K31 -> 26279.74
B14: Total Current Assets | C14: =SUM(C11:C13) -> 41281 | D14: =SUM(D11:D13) -> 62586 | E14: =SUM(E11:E13) -> 60409 | F14: =SUM(F11:F13) -> 104790 | G14: =SUM(G11:G13) -> 85216.381 | H14: =SUM(H11:H13) -> 93311.937 | I14: =SUM(I11:I13) -> 101710.01 | J14: =SUM(J11:J13) -> 110660.49 | K14: =SUM(K11:K13) -> 120398.62
B16: Current Liabilities
B17: Accounts Payable | C17: 27892 | D17: 20578 | E17: 23788 | F17: 32887 | G17: =+G8/365*G34 -> 20303.891 | H17: =+H8/365*H34 -> 22232.761 | I17: =+I8/365*I34 -> 24233.709 | J17: =+J8/365*J34 -> 26366.276 | K17: =+K8/365*K34 -> 28686.508
B18: Accrued Liabilities | C18: 51714 | D18: 66993 | E18: 66299 | F18: 67895 | G18: =+G7*G35 -> 83188.442 | H18: =+H7*H35 -> 91091.344 | I18: =+I7*I35 -> 99289.564 | J18: =+J7*J35 -> 108027.05 | K18: =+K7*K35 -> 117533.43
B19: Other Current Liabilities | C19: 30851 | D19: 50510 | E19: 39607 | F19: 41546 | G19: =+G7*G36 -> 54592.415 | H19: =+H7*H36 -> 59778.694 | I19: =+I7*I36 -> 65158.777 | J19: =+J7*J36 -> 70892.749 | K19: =+K7*K36 -> 77131.311
B20: Total Current Liabilities | C20: =SUM(C17:C19) -> 110457 | D20: =SUM(D17:D19) -> 138081 | E20: =SUM(E17:E19) -> 129694 | F20: =SUM(F17:F19) -> 142328 | G20: =SUM(G17:G19) -> 158084.75 | H20: =SUM(H17:H19) -> 173102.8 | I20: =SUM(I17:I19) -> 188682.05 | J20: =SUM(J17:J19) -> 205286.07 | K20: =SUM(K17:K19) -> 223351.25
B22: Net Working Capital | C22: =+C14-C20 -> -69176 | D22: =+D14-D20 -> -75495 | E22: =+E14-E20 -> -69285 | F22: =+F14-F20 -> -37538 | G22: =+G14-G20 -> -72868.367 | H22: =+H14-H20 -> -79790.862 | I22: =+I14-I20 -> -86972.039 | J22: =+J14-J20 -> -94625.579 | K22: =+K14-K20 -> -102952.63
B23: % sales | C23: =+IF(ISERROR(C22/C7),0,C22/C7) -> -0.11784206 | D23: =+IF(ISERROR(D22/D7),0,D22/D7) -> -0.080590581 | E23: =+IF(ISERROR(E22/E7),0,E22/E7) -> -0.064672191 | F23: =+IF(ISERROR(F22/F7),0,F22/F7) -> -0.031767336 | G23: =+IF(ISERROR(G22/G7),0,G22/G7) -> -0.056060378 | H23: =+IF(ISERROR(H22/H7),0,H22/H7) -> -0.056060378 | I23: =+IF(ISERROR(I22/I7),0,I22/I7) -> -0.056060378 | J23: =+IF(ISERROR(J22/J7),0,J22/J7) -> -0.056060378 | K23: =+IF(ISERROR(K22/K7),0,K22/K7) -> -0.056060378
B25: (Increase) / Decrease in NWC | D25: =+C22-D22 -> 6319 | E25: =+D22-E22 -> -6210 | F25: =+E22-F22 -> -31747 | G25: =+F22-G22 -> 35330.367 | H25: =+G22-H22 -> 6922.4948 | I25: =+H22-I22 -> 7181.1775 | J25: =+I22-J22 -> 7653.5394 | K25: =+J22-K22 -> 8327.0509
B27: Assumptions
B28: Current Assets
B29: Days Sales Outstanding | C29: =+IF(ISERROR(C11/C7*365),0,C11/C7*365) -> 16.947896 | D29: =+IF(ISERROR(D11/D7*365),0,D11/D7*365) -> 18.017543 | E29: =+IF(ISERROR(E11/E7*365),0,E11/E7*365) -> 14.271893 | F29: =+IF(ISERROR(F11/F7*365),0,F11/F7*365) -> 23.829247 | G29: ='AS2'!F7 -> 18.706312 | H29: ='AS2'!G7 -> 18.706312 | I29: ='AS2'!H7 -> 18.706312 | J29: ='AS2'!I7 -> 18.706312 | K29: ='AS2'!J7 -> 18.706312
B30: Days Inventory Held | C30: =+IF(ISERROR(C12/C8*365),0,C12/C8*365) -> 2.4775503 | D30: =+IF(ISERROR(D12/D8*365),0,D12/D8*365) -> 6.7314683 | E30: =+IF(ISERROR(E12/E8*365),0,E12/E8*365) -> 5.2734976 | F30: =+IF(ISERROR(F12/F8*365),0,F12/F8*365) -> 6.0708873 | G30: ='AS2'!F12 -> 0 | H30: ='AS2'!G12 -> 0 | I30: ='AS2'!H12 -> 0 | J30: ='AS2'!I12 -> 0 | K30: ='AS2'!J12 -> 0
B31: Prepaids and Other CA (% of sales) | C31: =+IF(ISERROR(C13/C7),0,C13/C7) -> 0.02192248 | D31: =+IF(ISERROR(D13/D7),0,D13/D7) -> 0.011825716 | E31: =+IF(ISERROR(E13/E7),0,E13/E7) -> 0.012920437 | F31: =+IF(ISERROR(F13/F7),0,F13/F7) -> 0.018193989 | G31: ='AS2'!F17 -> 0.01431 | H31: ='AS2'!G17 -> 0.01431 | I31: ='AS2'!H17 -> 0.01431 | J31: ='AS2'!I17 -> 0.01431 | K31: ='AS2'!J17 -> 0.01431
B33: Current Liabilities
B34: Days Payable Outstanding | C34: =+IF(ISERROR(C17/C8*365),0,C17/C8*365) -> 59.830158 | D34: =+IF(ISERROR(D17/D8*365),0,D17/D8*365) -> 26.304625 | E34: =+IF(ISERROR(E17/E8*365),0,E17/E8*365) -> 26.821886 | F34: =+IF(ISERROR(F17/F8*365),0,F17/F8*365) -> 32.485075 | G34: ='AS2'!F23 -> 18.1 | H34: ='AS2'!G23 -> 18.1 | I34: ='AS2'!H23 -> 18.1 | J34: ='AS2'!I23 -> 18.1 | K34: ='AS2'!J23 -> 18.1
B35: Accrued Liabilities (% of sales) | C35: =+IF(ISERROR(C18/C7),0,C18/C7) -> 0.088095356 | D35: =+IF(ISERROR(D18/D7),0,D18/D7) -> 0.071514734 | E35: =+IF(ISERROR(E18/E7),0,E18/E7) -> 0.061884991 | F35: =+IF(ISERROR(F18/F7),0,F18/F7) -> 0.057457598 | G35: ='AS2'!F28 -> 0.064 | H35: ='AS2'!G28 -> 0.064 | I35: ='AS2'!H28 -> 0.064 | J35: ='AS2'!I28 -> 0.064 | K35: ='AS2'!J28 -> 0.064
B36: Other Current Liabilities (% of sales) | C36: =+IF(ISERROR(C19/C7),0,C19/C7) -> 0.052555011 | D36: =+IF(ISERROR(D19/D7),0,D19/D7) -> 0.053919203 | E36: =+IF(ISERROR(E19/E7),0,E19/E7) -> 0.036970073 | F36: =+IF(ISERROR(F19/F7),0,F19/F7) -> 0.035159192 | G36: ='AS2'!F33 -> 0.042 | H36: ='AS2'!G33 -> 0.042 | I36: ='AS2'!H33 -> 0.042 | J36: ='AS2'!I33 -> 0.042 | K36: ='AS2'!J33 -> 0.042

Sheet WACC
B1: =Cover!G6 -> Planet Fitness, Inc.
B2: Weighted Average Cost of Capital Analysis
B3: ($ in thousands)
B6: WACC Calculation | F6: Comparable Companies Unlevered Beta
B7: Target Capital Structure | G7: Predicted | H7: Market | I7: Market | J7: Debt/ | K7: Marginal | L7: Unlevered
B8: Debt-to-Total Capitalization | D8: ='WACC Documentation'!D7 -> 0.25507847 | F8: Company | G8: Levered Beta (4) | H8: Value of Debt | I8: Value of Equity | J8: Equity | K8: Tax Rate | L8: Beta
B9: Equity-to-Total Capitalization | D9: =1-D8 -> 0.74492153 | F9: Xponential Fitness | G9: ='WACC Documentation'!D21 -> 1.41 | H9: ='WACC Documentation'!D25 -> 379623 | I9: 291551.01 | J9: =+IF(ISERROR(H9/I9),0,H9/I9) -> 1.3020809 | K9: 0.277 | L9: =+G9/(1+(J9)*(1-K9)) -> 0.72627833
F10: Life Time Group | G10: ='WACC Documentation'!D31 -> 1.68 | H10: ='WACC Documentation'!D35 -> 1535741 | I10: 6380000 | J10: =+IF(ISERROR(H10/I10),0,H10/I10) -> 0.24071176 | K10: 0.277 | L10: =+G10/(1+(J10)*(1-K10)) -> 1.4309629
B12: Cost of Debt
B13: Cost-of-Debt | D13: ='WACC Documentation'!D11 -> 0.038836455
B14: Tax Rate | D14: 0.277
B15: After-tax Cost of Debt | D15: =+D13*(1-D14) -> 0.028078757 | F15: Mean | G15: =AVERAGE(G9:G14) -> 1.545 | J15: =AVERAGE(J9:J14) -> 0.77139633 | L15: =AVERAGE(L9:L14) -> 1.0786206
F16: Median | G16: =MEDIAN(G9:G14) -> 1.545 | J16: =MEDIAN(J9:J14) -> 0.77139633 | L16: =MEDIAN(L9:L14) -> 1.0786206
B18: Cost of Equity | F18: ValueCo Relevered Beta
B19: Risk-free Rate (1) | D19: 0.04672 | I19: Mean | J19: Target | K19: Target
B20: Market Risk Premium (2) | D20: 0.0446 | I20: Unlevered | J20: Debt/ | K20: Marginal | L20: Relevered
B21: Levered Beta | D21: =+L22 -> 1.3456569 | I21: Beta | J21: Equity | K21: Tax Rate | L21: Beta
B22: Size Premium (3) | D22: 0.005 | F22: Relevered Beta | I22: =L15 -> 1.0786206 | J22: =D8/D9 -> 0.34242327 | K22: =D14 -> 0.277 | L22: =+I22*(1+(J22)*(1-K22)) -> 1.3456569
B23: Cost of Equity | D23: =+D19+(D21*D20)+D22 -> 0.1117363
F24: WACC Sensitivity Analysis
H25: Pre-tax Cost of Debt
B26: WACC | D26: =(D8*D15)+(D9*D23) -> 0.090397061 | F26: Debt-to-Total Capitalization | G26: =D26 -> 0.090397061 | H26: =I26-0.005 -> 0.028836455 | I26: =J26-0.005 -> 0.033836455 | J26: =D13 -> 0.038836455 | K26: =J26+0.005 -> 0.043836455 | L26: =K26+0.005 -> 0.048836455
G27: =G28-0.1 -> 0.055078468 | H27: 0.097392192 | I27: 0.097193083 | J27: 0.097193083 | K27: 0.097392192 | L27: 0.097790409
G28: =G29-0.1 -> 0.15507847 | H28: 0.10181187 | I28: 0.10197426 | J28: 0.10197426 | K28: 0.10181187 | L28: 0.10148708
G29: =D8 -> 0.25507847 | H29: 0.10181187 | I29: 0.10197426 | J29: 0.10197426 | K29: 0.10181187 | L29: 0.10148708
G30: =G29+0.1 -> 0.35507847 | H30: 0.097392192 | I30: 0.097193083 | J30: 0.097193083 | K30: 0.097392192 | L30: 0.097790409
G31: =G30+0.1 -> 0.45507847 | H31: 0.088552844 | I31: 0.087630735 | J31: 0.087630735 | K31: 0.088552844 | L31: 0.090397061
B33: (1) Interpolated yield on 20-year U.S. Treasury, sourced from US Treasury
B34: (2) Tax rate obtained from 10k
B35: (3) Mid-cap Decile size premium based on market capitalization, per Ibbotson
B36: (4) MRP Sourced from Damodaran

Sheet WACC Documentation
C1: WACC | H1: 2024 | I1: 2023 | J1: 2022 | K1: 2021
C2: Share Price | D2: 90.65 | E2: pitchbook | F2: https://my.pitchbook.com/gs/all
C3: Shares Outstanding | D3: 82983165 | E3: pitchbook | F3: https://my.pitchbook.com/gs/all
B4: (in thousands) | C4: Market Cap | D4: =D2*D3/1000 -> 7522423.9 | G4: Total Current Debt & Capital Lease Obligation | H4: 22500 | I4: 20750 | J4: 20750 | K4: 17500 | L4: pitchbook
G5: Total Long Term Debt and Capital Lease Obligation | H5: 2553353 | I5: 2344463 | J5: 2319974 | K5: 1937955 | L5: pitchbook
C6: Equity to total | D6: =D4/(D4+H6) -> 0.74492153 | G6: Total Debt | H6: =SUM(H4:H5) -> 2575853 | I6: =SUM(I4:I5) -> 2365213 | J6: =SUM(J4:J5) -> 2340724 | K6: =SUM(K4:K5) -> 1955455
C7: Debt to total | D7: =H6/(D4+H6) -> 0.25507847
C9: Interest Expense | D9: 100037 | E9: pitchbook | F9: https://my.pitchbook.com/gs/all
C10: Total Debt | D10: =H6 -> 2575853
C11: Cost of Debt | D11: =D9/D10 -> 0.038836455 | F11: RFR | G11: Daily Treasury rates | U.S. Department of the Treasury. (2025, December 23). U.S. Department of The Treasury. https://home.treasury.gov/resource-center/data-chart-center/interest-rates/TextView?type=daily_treasury_yield_curve&field_tdr_date_value=202602
D13: 0.0485 | F13: MRP | G13: Damodaran online: Home page for Aswath Damodaran. (n.d.). https://pages.stern.nyu.edu/~adamodar/
C20: Xponential Fitness
C21: Predicted levered beta | D21: 1.41 | E21: Yahoo Finance. (n.d.-b). Yahoo Finance. Retrieved February 15, 2026, from https://finance.yahoo.com/quote/XPOF/key-statistics/
C22: Market Value of Equity | D22: 291900 | E22: pitchbook | F22: https://my.pitchbook.com/gs/all
C23: Total Current Debt & Capital Lease Obligation (FY2024) | D23: 14023 | E23: pitchbook | F23: https://my.pitchbook.com/gs/all
C24: Total Long Term Debt and Capital Lease Obligation (FY2024) | D24: 365600 | E24: pitchbook | F24: https://my.pitchbook.com/gs/all
C25: Total Debt (FY2024) | D25: =SUM(D23:D24) -> 379623
C27: EV/EBITDA | D27: 9.19
C30: Life Time Group
C31: Predicted levered beta | D31: 1.68 | E31: Yahoo Finance. (n.d.). Yahoo Finance. Retrieved February 15, 2026, from https://finance.yahoo.com/quote/LTH/key-statistics/
C32: Market Value of Equity | D32: 6410000 | E32: pitchbook | F32: https://my.pitchbook.com/gs/all
C33: Total Current Debt & Capital Lease Obligation (FY2024) | D33: 22584 | E33: pitchbook | F33: https://my.pitchbook.com/gs/all
C34: Total Long Term Debt and Capital Lease Obligation (FY2024) | D34: 1513157 | E34: pitchbook | F34: https://my.pitchbook.com/gs/all
C35: Total Debt (FY2024) | D35: =SUM(D33:D34) -> 1535741
C37: EV/EBITDA | D37: 13.5
C39: The BeachBody Company
C40: Predicted levered beta | D40: 1.1 | E40: Yahoo Finance. (n.d.-g). Yahoo Finance. Retrieved February 15, 2026, from https://finance.yahoo.com/quote/BODI/key-statistics/
C41: Market Value of Equity | D41: 62800 | E41: (we didnt take this because it was not reliable)
C42: Current Portion of Term Loan | D42: 9500
C43: Long Term Loan | D43: 9668
C44: Lease Debt | D44: 3311
C45: Total Debt (FY2024) | D45: =SUM(D42:D44) -> 22479
C47: EV/EBITDA
C50: Peloton Interactive
C51: Predicted levered beta | D51: 2.44 | E51: Yahoo Finance. (n.d.-g). Yahoo Finance. Retrieved February 15, 2026, from https://finance.yahoo.com/quote/PTON/key-statistics/
C52: Market Value of Equity | D52: 3540000 | E52: (we didnt take this because fiscal year was scattered and mismatched)
C53: Current Portion of Term Loan
C54: Long Term Loan
C55: Lease Debt
C56: Total Debt (FY2024) | D56: 2078700
...

Sheet AS1
B1: Assumptions Page 1 - Income Statement and Cash Flow Statement
F2: Projection Period
F3: 1 | G3: 2 | H3: 3 | I3: 4 | J3: 5 | K3: 6 | L3: 7 | M3: 8 | N3: 9 | O3: 10
F4: =+DCF!J6 -> 2025 | G4: =+DCF!K6 -> 2026 | H4: =+DCF!L6 -> 2027 | I4: =+DCF!M6 -> 2028 | J4: =+DCF!N6 -> 2029 | K4: =+J4+1 -> 2030 | L4: =+K4+1 -> 2031 | M4: =+L4+1 -> 2032 | N4: =+M4+1 -> 2033 | O4: =+N4+1 -> 2034
B6: Income Statement Assumptions
B7: Sales (% growth) | F7: =CHOOSE(DCF!$D$4,F8,F9,F10,#REF!,#REF!) -> 0.1 | G7: =CHOOSE(DCF!$D$4,G8,G9,G10,#REF!,#REF!) -> 0.095 | H7: =CHOOSE(DCF!$D$4,H8,H9,H10,#REF!,#REF!) -> 0.09 | I7: =CHOOSE(DCF!$D$4,I8,I9,I10,#REF!,#REF!) -> 0.088 | J7: =CHOOSE(DCF!$D$4,J8,J9,J10,#REF!,#REF!) -> 0.088 | K7: =CHOOSE(DCF!$D$4,K8,K9,K10,#REF!,#REF!) -> 0.088 | L7: =CHOOSE(DCF!$D$4,L8,L9,L10,#REF!,#REF!) -> 0.088 | M7: =CHOOSE(DCF!$D$4,M8,M9,M10,#REF!,#REF!) -> 0.088 | ... O7: =CHOOSE(DCF!$D$4,O8,O9,O10,#REF!,#REF!) -> 0.088
B8: Base | E8: 1 | F8: ='Assumptions 1 Documentation'!C14 -> 0.1 | G8: ='Assumptions 1 Documentation'!C15 -> 0.095 | H8: ='Assumptions 1 Documentation'!C16 -> 0.09 | I8: ='Assumptions 1 Documentation'!C17 -> 0.088 | J8: =I8 -> 0.088 | K8: =J8 -> 0.088 | L8: =K8 -> 0.088 | M8: =L8 -> 0.088 | N8: =M8 -> 0.088 | O8: =N8 -> 0.088
B9: Upside | E9: 2 | F9: ='Assumptions 1 Documentation'!C26 -> 0.1230349 | G9: ='Assumptions 1 Documentation'!C27 -> 0.11786058 | H9: ='Assumptions 1 Documentation'!C28 -> 0.11219337 | I9: ='Assumptions 1 Documentation'!C29 -> 0.10956873 | J9: =I9 -> 0.10956873 | K9: =J9 -> 0.10956873 | L9: =K9 -> 0.10956873 | M9: =L9 -> 0.10956873 | N9: =M9 -> 0.10956873 | O9: =N9 -> 0.10956873
B10: Downside | E10: 3 | F10: ='Assumptions 1 Documentation'!C38 -> 0.065 | G10: ='Assumptions 1 Documentation'!C39 -> 0.06 | H10: ='Assumptions 1 Documentation'!C40 -> 0.055 | I10: ='Assumptions 1 Documentation'!C41 -> 0.053 | J10: =I10 -> 0.053 | K10: =J10 -> 0.053 | L10: =K10 -> 0.053 | M10: =L10 -> 0.053 | N10: =M10 -> 0.053 | O10: =N10 -> 0.053
B12: Cost of Goods Sold (% sales) | F12: =CHOOSE(DCF!$D$4,F13,F14,F15,#REF!,#REF!) -> 0.315 | G12: =CHOOSE(DCF!$D$4,G13,G14,G15,#REF!,#REF!) -> 0.315 | H12: =CHOOSE(DCF!$D$4,H13,H14,H15,#REF!,#REF!) -> 0.315 | I12: =CHOOSE(DCF!$D$4,I13,I14,I15,#REF!,#REF!) -> 0.315 | J12: =CHOOSE(DCF!$D$4,J13,J14,J15,#REF!,#REF!) -> 0.315 | K12: =CHOOSE(DCF!$D$4,K13,K14,K15,#REF!,#REF!) -> 0.315 | L12: =CHOOSE(DCF!$D$4,L13,L14,L15,#REF!,#REF!) -> 0.315 | M12: =CHOOSE(DCF!$D$4,M13,M14,M15,#REF!,#REF!) -> 0.315 | ... O12: =CHOOSE(DCF!$D$4,O13,O14,O15,#REF!,#REF!) -> 0.315
B13: Base | E13: 1 | F13: ='Assumptions 1 Documentation'!$V$12 -> 0.315 | G13: ='Assumptions 1 Documentation'!$V$12 -> 0.315 | H13: ='Assumptions 1 Documentation'!$V$12 -> 0.315 | I13: ='Assumptions 1 Documentation'!$V$12 -> 0.315 | J13: ='Assumptions 1 Documentation'!$V$12 -> 0.315 | K13: ='Assumptions 1 Documentation'!$V$12 -> 0.315 | L13: ='Assumptions 1 Documentation'!$V$12 -> 0.315 | M13: ='Assumptions 1 Documentation'!$V$12 -> 0.315 | ... O13: ='Assumptions 1 Documentation'!$V$12 -> 0.315
B14: Upside | E14: 2 | F14: ='Assumptions 1 Documentation'!$V$18 -> 0.305 | G14: ='Assumptions 1 Documentation'!$V$18 -> 0.305 | H14: ='Assumptions 1 Documentation'!$V$18 -> 0.305 | I14: ='Assumptions 1 Documentation'!$V$18 -> 0.305 | J14: ='Assumptions 1 Documentation'!$V$18 -> 0.305 | K14: ='Assumptions 1 Documentation'!$V$18 -> 0.305 | L14: ='Assumptions 1 Documentation'!$V$18 -> 0.305 | M14: ='Assumptions 1 Documentation'!$V$18 -> 0.305 | ... O14: ='Assumptions 1 Documentation'!$V$18 -> 0.305
B15: Downside | E15: 3 | F15: ='Assumptions 1 Documentation'!$V$23 -> 0.325 | G15: ='Assumptions 1 Documentation'!$V$23 -> 0.325 | H15: ='Assumptions 1 Documentation'!$V$23 -> 0.325 | I15: ='Assumptions 1 Documentation'!$V$23 -> 0.325 | J15: ='Assumptions 1 Documentation'!$V$23 -> 0.325 | K15: ='Assumptions 1 Documentation'!$V$23 -> 0.325 | L15: ='Assumptions 1 Documentation'!$V$23 -> 0.325 | M15: ='Assumptions 1 Documentation'!$V$23 -> 0.325 | ... O15: ='Assumptions 1 Documentation'!$V$23 -> 0.325
B17: SG&A (% sales) | F17: =CHOOSE(DCF!$D$4,F18,F19,F20,#REF!,#REF!) -> 0.1 | G17: =CHOOSE(DCF!$D$4,G18,G19,G20,#REF!,#REF!) -> 0.1 | H17: =CHOOSE(DCF!$D$4,H18,H19,H20,#REF!,#REF!) -> 0.1 | I17: =CHOOSE(DCF!$D$4,I18,I19,I20,#REF!,#REF!) -> 0.1 | J17: =CHOOSE(DCF!$D$4,J18,J19,J20,#REF!,#REF!) -> 0.1 | K17: =CHOOSE(DCF!$D$4,K18,K19,K20,#REF!,#REF!) -> 0.1 | L17: =CHOOSE(DCF!$D$4,L18,L19,L20,#REF!,#REF!) -> 0.1 | M17: =CHOOSE(DCF!$D$4,M18,M19,M20,#REF!,#REF!) -> 0.1 | ... O17: =CHOOSE(DCF!$D$4,O18,O19,O20,#REF!,#REF!) -> 0.1
B18: Base | E18: 1 | F18: ='Assumptions 1 Documentation'!$AL$13 -> 0.1 | G18: ='Assumptions 1 Documentation'!$AL$13 -> 0.1 | H18: ='Assumptions 1 Documentation'!$AL$13 -> 0.1 | I18: ='Assumptions 1 Documentation'!$AL$13 -> 0.1 | J18: ='Assumptions 1 Documentation'!$AL$13 -> 0.1 | K18: ='Assumptions 1 Documentation'!$AL$13 -> 0.1 | L18: ='Assumptions 1 Documentation'!$AL$13 -> 0.1 | M18: ='Assumptions 1 Documentation'!$AL$13 -> 0.1 | ... O18: ='Assumptions 1 Documentation'!$AL$13 -> 0.1
B19: Upside | E19: 2 | F19: ='Assumptions 1 Documentation'!$AL$19 -> 0.095 | G19: ='Assumptions 1 Documentation'!$AL$19 -> 0.095 | H19: ='Assumptions 1 Documentation'!$AL$19 -> 0.095 | I19: ='Assumptions 1 Documentation'!$AL$19 -> 0.095 | J19: ='Assumptions 1 Documentation'!$AL$19 -> 0.095 | K19: ='Assumptions 1 Documentation'!$AL$19 -> 0.095 | L19: ='Assumptions 1 Documentation'!$AL$19 -> 0.095 | M19: ='Assumptions 1 Documentation'!$AL$19 -> 0.095 | ... O19: ='Assumptions 1 Documentation'!$AL$19 -> 0.095
B20: Downside | E20: 3 | F20: ='Assumptions 1 Documentation'!$AL$26 -> 0.11 | G20: ='Assumptions 1 Documentation'!$AL$26 -> 0.11 | H20: ='Assumptions 1 Documentation'!$AL$26 -> 0.11 | I20: ='Assumptions 1 Documentation'!$AL$26 -> 0.11 | J20: ='Assumptions 1 Documentation'!$AL$26 -> 0.11 | K20: ='Assumptions 1 Documentation'!$AL$26 -> 0.11 | L20: ='Assumptions 1 Documentation'!$AL$26 -> 0.11 | M20: ='Assumptions 1 Documentation'!$AL$26 -> 0.11 | ... O20: ='Assumptions 1 Documentation'!$AL$26 -> 0.11
B22: Depreciation & Amortization (% sales) | F22: =CHOOSE(DCF!$D$4,F23,F24,F25,#REF!,#REF!) -> 0.13566667 | G22: =CHOOSE(DCF!$D$4,G23,G24,G25,#REF!,#REF!) -> 0.13566667 | H22: =CHOOSE(DCF!$D$4,H23,H24,H25,#REF!,#REF!) -> 0.13566667 | I22: =CHOOSE(DCF!$D$4,I23,I24,I25,#REF!,#REF!) -> 0.13566667 | J22: =CHOOSE(DCF!$D$4,J23,J24,J25,#REF!,#REF!) -> 0.13566667 | K22: =CHOOSE(DCF!$D$4,K23,K24,K25,#REF!,#REF!) -> 0.13566667 | L22: =CHOOSE(DCF!$D$4,L23,L24,L25,#REF!,#REF!) -> 0.13566667 | M22: =CHOOSE(DCF!$D$4,M23,M24,M25,#REF!,#REF!) -> 0.13566667 | ... O22: =CHOOSE(DCF!$D$4,O23,O24,O25,#REF!,#REF!) -> 0.13566667
B23: Base | E23: 1 | F23: ='Assumptions 1 Documentation'!$BE$11 -> 0.13566667 | G23: ='Assumptions 1 Documentation'!$BE$11 -> 0.13566667 | H23: ='Assumptions 1 Documentation'!$BE$11 -> 0.13566667 | I23: ='Assumptions 1 Documentation'!$BE$11 -> 0.13566667 | J23: ='Assumptions 1 Documentation'!$BE$11 -> 0.13566667 | K23: ='Assumptions 1 Documentation'!$BE$11 -> 0.13566667 | L23: ='Assumptions 1 Documentation'!$BE$11 -> 0.13566667 | M23: ='Assumptions 1 Documentation'!$BE$11 -> 0.13566667 | ... O23: ='Assumptions 1 Documentation'!$BE$11 -> 0.13566667
B24: Upside | E24: 2 | F24: ='Assumptions 1 Documentation'!$BE$18 -> 0.139 | G24: ='Assumptions 1 Documentation'!$BE$18 -> 0.139 | H24: ='Assumptions 1 Documentation'!$BE$18 -> 0.139 | I24: ='Assumptions 1 Documentation'!$BE$18 -> 0.139 | J24: ='Assumptions 1 Documentation'!$BE$18 -> 0.139 | K24: ='Assumptions 1 Documentation'!$BE$18 -> 0.139 | L24: ='Assumptions 1 Documentation'!$BE$18 -> 0.139 | M24: ='Assumptions 1 Documentation'!$BE$18 -> 0.139 | ... O24: ='Assumptions 1 Documentation'!$BE$18 -> 0.139
B25: Downside | E25: 3 | F25: ='Assumptions 1 Documentation'!$BE$23 -> 0.13 | G25: ='Assumptions 1 Documentation'!$BE$23 -> 0.13 | H25: ='Assumptions 1 Documentation'!$BE$23 -> 0.13 | I25: ='Assumptions 1 Documentation'!$BE$23 -> 0.13 | J25: ='Assumptions 1 Documentation'!$BE$23 -> 0.13 | K25: ='Assumptions 1 Documentation'!$BE$23 -> 0.13 | L25: ='Assumptions 1 Documentation'!$BE$23 -> 0.13 | M25: ='Assumptions 1 Documentation'!$BE$23 -> 0.13 | ... O25: ='Assumptions 1 Documentation'!$BE$23 -> 0.13
B27: Cash Flow Statement Assumptions
B28: Capital Expenditures (% of sales) | F28: =CHOOSE(DCF!$D$4,F29,F30,F31,#REF!,#REF!) -> 0.11735789 | G28: =CHOOSE(DCF!$D$4,G29,G30,G31,#REF!,#REF!) -> 0.11068898 | H28: =CHOOSE(DCF!$D$4,H29,H30,H31,#REF!,#REF!) -> 0.10477229 | I28: =CHOOSE(DCF!$D$4,I29,I30,I31,#REF!,#REF!) -> 0.099260166 | J28: =CHOOSE(DCF!$D$4,J29,J30,J31,#REF!,#REF!) -> 0.093954294 | K28: =CHOOSE(DCF!$D$4,K29,K30,K31,#REF!,#REF!) -> 0.093954294 | L28: =CHOOSE(DCF!$D$4,L29,L30,L31,#REF!,#REF!) -> 0.093954294 | M28: =CHOOSE(DCF!$D$4,M29,M30,M31,#REF!,#REF!) -> 0.093954294 | ... O28: =CHOOSE(DCF!$D$4,O29,O30,O31,#REF!,#REF!) -> 0.093954294
B29: Base | E29: 1 | F29: ='Assumptions 1 Documentation'!CH41 -> 0.11735789 | G29: ='Assumptions 1 Documentation'!CH42 -> 0.11068898 | H29: ='Assumptions 1 Documentation'!CH43 -> 0.10477229 | I29: ='Assumptions 1 Documentation'!CH44 -> 0.099260166 | J29: ='Assumptions 1 Documentation'!CH45 -> 0.093954294 | K29: =J29 -> 0.093954294 | L29: =K29 -> 0.093954294 | M29: =L29 -> 0.093954294 | N29: =M29 -> 0.093954294 | O29: =N29 -> 0.093954294
B30: Upside | E30: 2 | F30: ='Assumptions 1 Documentation'!CH55 -> 0.13755657 | G30: ='Assumptions 1 Documentation'!CH56 -> 0.12810903 | H30: ='Assumptions 1 Documentation'!CH57 -> 0.11973155 | I30: ='Assumptions 1 Documentation'!CH58 -> 0.11200493 | J30: ='Assumptions 1 Documentation'!CH59 -> 0.10463675 | K30: =J30 -> 0.10463675 | L30: =K30 -> 0.10463675 | M30: =L30 -> 0.10463675 | N30: =M30 -> 0.10463675 | O30: =N30 -> 0.10463675
B31: Downside | E31: 3 | F31: ='Assumptions 1 Documentation'!CH69 -> 0.097377018 | G31: ='Assumptions 1 Documentation'!CH70 -> 0.093739145 | H31: ='Assumptions 1 Documentation'!CH71 -> 0.090628605 | I31: ='Assumptions 1 Documentation'!CH72 -> 0.087753979 | J31: ='Assumptions 1 Documentation'!CH73 -> 0.084939133 | K31: =J31 -> 0.084939133 | L31: =K31 -> 0.084939133 | M31: =L31 -> 0.084939133 | N31: =M31 -> 0.084939133 | O31: =N31 -> 0.084939133

Sheet Assumptions 1 Documentation
B1: =Cover!G6 -> Planet Fitness, Inc.
B3: SALES GROWTH ASSUMPTIONS | E3: Source: Planet Fitness, Inc. (2025). Form 10-K for the fiscal year ended December 31, 2024. U.S. Securities and Exchange Commission. | U3: COGS ASSUMPTIONS | W3: Source: Planet Fitness, Inc. (2025). Form 10-K for the fiscal year ended December 31, 2024. U.S. Securities and Exchange Commission. | AK3: SG&A (% of Sales) ASSUMPTIONS | AO3: Source: Planet Fitness, Inc. (2025). Form 10-K for the fiscal year ended December 31, 2024. U.S. Securities and Exchange Commission. | BD3: D&A (% of Sales) ASSUMPTIONS | BH3: Source: Planet Fitness, Inc. (2025). Form 10-K for the fiscal year ended December 31, 2024. U.S. Securities and Exchange Commission. | BZ3: Capital Expenditures (% of sales) ASSUMPTIONS | CE3: Source: Planet Fitness, Inc. (2025). Form 10-K for the fiscal year ended December 31, 2024. U.S. Securities and Exchange Commission.
C4: 2022 | D4: 2023 | E4: 2024 | F4: Trend | V4: 2022 | W4: 2023 | X4: 2024 | Y4: Trend | AL4: 2022 | AM4: 2023 | AN4: 2024 | AO4: Trend | BE4: 2022 | BF4: 2023 | BG4: 2024 | BH4: Trend | CA4: 2022 | CB4: 2023 | CC4: 2024 | CD4: Trend
B5: Sales (% growth) | C5: 0.59580119 | D5: 0.1436358 | E5: 0.10298266 | F5: ↘ Slowing down | U5: COGS % Sales | V5: 0.305 | W5: 0.302 | X5: 0.313 | Y5: ↗ Increasing | AK5: SG&A % Sales | AL5: 0.123 | AM5: 0.117 | AN5: 0.109 | AO5: ↘ Improving | BD5: D&A % Sales | BE5: 0.132 | BF5: 0.139 | BG5: 0.136 | BH5: → Stable | BZ5: Capex to Sales | CA5: 0.10681041 | CB5: 0.12693242 | CC5: 0.13122369 | CD5: ↗ Growing up
CC6: Higher capital expenditures primarily from new corporate-owned clubs
B7: For the Base Scenario: | U7: For the Base Scenario: | AK7: For the Base Scenario: | BD7: For the Base Scenario:
B8: 1. Company guidance: Expected to open 900 additional clubs, including more than 500 over the next three years Source: Planet Fitness 10-K 2024, p. 4 | U8: In the Last 3 years the COGS (% of Sales) have increased an average of -1.1pp from 2023 to 2024. | AK8: As the company say in the 10K "Increase primarily attributable to higher consulting costs from strategic initiatives and CEO transition payroll costs" (Planet Fitness, 2025, Results of Operations, p.53) | BD8: As the company say in the 10K "This increase was primarily attributable to new clubs opened and acquired since January 1, 2023." (Planet Fitness, 2025, Results of Operations, p.53) | BZ8: In 2024 $515.3 million sales attributable to our corporate-owned clubs. Of the PNLT 2,722 clubs, 277 are corporate-owned.
B9: - 500 clubs / 3 years = 167 clubs/year (average) 2024 base: 2,722 clubs 167 / 2,722 = 6.1% unit growth potential | U9: In the 10K of 2024, PLNT have declared "higher margin equipment sales related to an updated equipment mix as a result of the adoption of the franchise growth model" | AK9: Based on the last years improvement we can see one clear trend: -0.6 to -0.8pp annual | BD9: Linkage to Capex: D&A follows Capex with ~3-5 year lag. In 2024 Capex: $155M (13.1% of sales). If Capex stable at ~13-14% of sales, D&A should stabilize around 13.5%. Source: (Planet Fitness 10-K, 2024, Cash Flow Statement, p. 55) | BZ9: In 2023 $475.8 million sales attributable to our corporate-owned stores. Of our 2,575 stores, 256 are corporate-owned.
B10: 2. Historical growth: 12.3% CAGR (2021-2023) (Calculation based on Planet Fitness Income Statement PitchBook) | U10: Because of that we assume that continuation of recent trend with modest inflation | AK10: For 2025 the company will not have the cost with the CEO transition costs that will reduce more the SG&A | BZ10: So in 2022 to 2023, they create 18 stores (+7.69%) (the according of the 2024 10K, p.47). In 2023 to 2024 they create 21 corporate-owned stores (+8.2%)
B11: 3.US Health & Fitness Club Market is expected to grow at a CAGR of 8.8% from 2024 to 2030 (Grand View Research, 2024, https://www.grandviewresearch.com/industry-analysis/us-health-fitness-club-market) | AK11: And with our assumption to growth in sales we assume that for the SG&A forecast will be: | BD11: 2025 to 2034 | BE11: =AVERAGE(BE5:BG5) -> 0.13566667 | BF11: Avg of the last three years | BZ11: In the capital Expenditure table. Source: Planet Fitness 10-K, 2024, Investing activities, p. 55 and p.56 and Planet Fitness 10-K, 2023, Investing activities, p. 55 and p.56
U12: 2025 to 2034 | V12: 0.315
B13: Year | C13: Growth | AK13: 2025 to 2034 | AL13: 0.1 | BD13: For the Upside Scenario: | BZ13: Capex Last 3 Years
B14: 2025 | C14: 0.1 | U14: For the Upside Scenario: | BD14: If GDP grows and demand increases, the company needs to invest in new factories, IT, or fleets. This new CAPEX will generate new depreciation lines. | BZ14: Components | CA14: 2022 | CB14: 2023 | CC14: 2024
B15: 2026 | C15: 0.095 | D15: Gradual moderation toward industry rate | U15: Because of your expectations in Sales Growth and thinging about the business of the company that have a portion of sales in equipments | AK15: For the Upside Scenario: | BD15: Therefore, the optimistic revenue scenario is usually accompanied by a higher D&A in the future. We are assuming more clubs, so more Capex and more future D&A | BZ15: New clubs | CA15: $40.8M | CB15: $52.6M | CC15: $65.4M
B16: 2027 | C16: 0.09 | D16: Converging to industry | U16: the assumption are the company will continue shift to higher-margin equipment package so less 1pp in the COGS | AK16: In upside revenue scenario (12.3% vs 10% base), SG&A leverage accelerates. | BD16: In 2024 | BZ16: Existing clubs | CA16: $43.3M | CB16: $59.6M | CC16: $66.4M
B17: 2028 to 2034 | C17: 0.088 | D17: Aligned with industry expectetions of CAGR (8.8%) | AK17: Source: (Analyst estimate based on operating leverage) | BZ17: IT systems | CA17: $15.8M | CB17: $23.6M | CC17: $22.2M
U18: 2025 to 2034 | V18: 0.305 | BD18: 2025 to 2034 | BE18: =BF5 -> 0.139 | BF18: the same as the highest in the last 3 years | BZ18: Corporate/other | CA18: $ 0.2M | CB18: $ 0.2M | CC18: $ 1.1M
B19: For Upside Scenario: Strong Economic Growth | AK19: 2025 to 2034 | AL19: 0.095 | BZ19: TOTAL | CA19: $100.1M | CB19: $136.0M | CC19: $155.1M
B20: 1.I search the GDP for the next years in FRED (https://fred.stlouisfed.org/series/GDPPOT#) and calculate the expected growth per year. And i use this growth to imagine one best scenario possible where the company follow the GDP Growth percentage (GDP in another sheet) | U20: For the Downside Scenario: | BD20: For the Downside Scenario:
U21: Because of your expectations in recessions, input cost inflation (materials, freight) and the franchisees delay club openings (less equipment sales) one bigger COGS | AK21: For the Downside Scenario: | BD21: D&A remains elevated in 2025 (reflects 2024 Capex), then declines as low Capex (9.7%) | BZ21: % of Sales | CA21: 0.107 | CB21: 0.127 | CC21: 0.131 | CD21: +2.4pp
B22: 2. Historical Correlation: During 2021-2022 economic recovery, PLNT grew 14%+ (Planet Fitness 10-K, 2022-2023) | AK22: Revenue grows only 6.5% vs 10% base case. Fixed SG&A components (rent, base salaries) spread over smaller revenue increase.
B23: 3. Accelerated Execution. In strong economy, franchisees accelerate openings Changing the number of open clubs per year: 200 clubs/year vs 167 base case. Exist the possibility of 7.4% unit growth vs 6.1% | U23: 2025 to 2034 | V23: 0.325 | AK23: Salary inflation continues (3-4%) even in recession. | BD23: 2025 to 2034 | BE23: 0.13 | BZ23: Cost New Clubs | CB23: per new club
AK24: (Conservative assumption based on fixed cost structure analysis) | BZ24: 2022 | CA24: $40.8M / 14 clubs | CB24: =40.8/14 -> 2.9142857 | CC24: Millions
B25: Year | C25: Growth | BZ25: 2023 | CA25: $52.6M / 18 clubs | CB25: =52.6/18 -> 2.9222222 | CC25: Millions
B26: 2025 | C26: 0.1230349 | AK26: 2025 to 2034 | AL26: 0.11 | BZ26: 2024 | CA26: $65.4M / 21 clubs | CB26: =65.4/21 -> 3.1142857 | CC26: Millions
B27: 2026 | C27: 0.11786058
B28: 2027 | C28: 0.11219337 | BZ28: Existing Clubs
B29: 2028 to 2034 | C29: 0.10956873 | BZ29: 2022 | CA29: $43.3M
BZ30: 2023 | CA30: $59.6M / 234 | CB30: =59.6/234 -> 0.25470085 | CC30: Millions
B31: For Downside Scenario: | BZ31: 2024 | CA31: $66.4M / 256 | CB31: =66.4/256 -> 0.259375 | CC31: Millions
B32: For this scenario, I compared the years 2019 with 2020, where we had a strong economic recession. | K32: Sources: (PitchBook https://my.pitchbook.com/profile/55520-74/company/financials/INCOME_STATEMENT)
B33: PLNT demonstrated resilience but growth slowed materially vs pre-pandemic trends. | BZ33: For the Base Scenario:
B34: 1. Company guidance of 500+ clubs assumes normal economic conditions. In recession, franchisees delay expansion plans. | BZ34: We are assuming that the company will create 20 new corporate clubs per year.
B35: Assumption: 100 clubs/year vs 167 base case → 3.7% unit growth vs 6.1% | BZ35: Per club Cost we are assuming 3M.
BZ36: Existing Club we are assuming 250k or 0.25 M
B37: Year | C37: Growth | BZ37: The rest lines we assume that will be the same as 2024
B38: 2025 | C38: =C14-3.5% -> 0.065 | D38: -3.5pp adjustment represents material but realistic downside scenario without assuming complete market collapse. PLNT's value positioning provides relative resilience vs premium competitors.
B39: 2026 | C39: =C15-3.5% -> 0.06 | BY39: Year | BZ39: New Clubs (#) | CA39: New clubs | CB39: Existing clubs (#) | CC39: Existing clubs | CD39: IT systems | CE39: Corporate/other | CF39: Capex | CG39: Revenue | CH39: % Capex
B40: 2027 | C40: =C16-3.5% -> 0.055 | BY40: 2024 | BZ40: 21 | CA40: 65.4 | CB40: 256 | CC40: 66.4 | CD40: 22.2 | CE40: 1.1 | CF40: =CA40+CC40+CD40+CE40 -> 155.1 | CG40: 1181.7 | CH40: =CF40/CG40 -> 0.13125159
B41: 2028 to 2034 | C41: =C17-3.5% -> 0.053 | BY41: 2025 | BZ41: 20 | CA41: =BZ41*3 -> 60 | CB41: =CB40+BZ40 -> 277 | CC41: =CB41*0.25 -> 69.25 | CD41: 22.2 | CE41: 1.1 | CF41: =CA41+CC41+CD41+CE41 -> 152.55 | CG41: =CG40*(1+C14) -> 1299.87 | CH41: =CF41/CG41 -> 0.11735789
...

Sheet GDP
A1: =Cover!G6 -> Planet Fitness, Inc.
A3: FRED Graph Observations
A4: Federal Reserve Economic Data, Federal Reserve Bank of St. Louis
A5: Link: https://fred.stlouisfed.org
A6: Help: https://fredhelp.stlouisfed.org
A7: This data may be copyrighted. Please refer to the Terms of Use: https://fred.stlouisfed.org/legal#fred-terms-faq
A8: File Created: 2026-02-17 1:34 pm CST
A9: Data Updated: 2025-03-17
A10: GDPPOT | B10: Real Potential Gross Domestic Product, Billions of Chained 2017 Dollars, Annual, Not Seasonally Adjusted
A12: observation_date | B12: GDPPOT | C12: Growth
A13: 45292 | B13: 22915.665
A14: 45658 | B14: 23443.525 | C14: =B14/B13-1 -> 0.023034898
A15: 46023 | B15: 23979.458 | C15: =B15/B14-1 -> 0.022860577
A16: 46388 | B16: 24511.643 | C16: =B16/B15-1 -> 0.022193371
A17: 46753 | B17: 25040.327 | C17: =B17/B16-1 -> 0.02156873
A18: 47119 | B18: 25565.52 | C18: =B18/B17-1 -> 0.020973867
A19: 47484 | B19: 26080.053 | C19: =B19/B18-1 -> 0.020126033
A20: 47849 | B20: 26585.798 | C20: =B20/B19-1 -> 0.019392024
A21: 48214 | B21: 27086.588 | C21: =B21/B20-1 -> 0.018836749
A22: 48580 | B22: 27582.27 | C22: =B22/B21-1 -> 0.018299924
A23: 48945 | B23: 28078.165 | C23: =B23/B22-1 -> 0.01797876
A24: 49310 | B24: 28572.438 | C24: =B24/B23-1 -> 0.017603447

Sheet AS2
B1: Assumptions Page 2 - Balance Sheet
F2: Projection Period
F3: 1 | G3: 2 | H3: 3 | I3: 4 | J3: 5 | K3: 6 | L3: 7 | M3: 8 | N3: 9 | O3: 10
F4: =+DCF!J6 -> 2025 | G4: =+DCF!K6 -> 2026 | H4: =+DCF!L6 -> 2027 | I4: =+DCF!M6 -> 2028 | J4: =+DCF!N6 -> 2029 | K4: =+J4+1 -> 2030 | L4: =+K4+1 -> 2031 | M4: =+L4+1 -> 2032 | N4: =+M4+1 -> 2033 | O4: =+N4+1 -> 2034
B6: Current Assets
B7: Days Sales Outstanding (DSO) | F7: =CHOOSE(DCF!$D$4,F8,F9,F10,#REF!,#REF!) -> 18.706312 | G7: =CHOOSE(DCF!$D$4,G8,G9,G10,#REF!,#REF!) -> 18.706312 | H7: =CHOOSE(DCF!$D$4,H8,H9,H10,#REF!,#REF!) -> 18.706312 | I7: =CHOOSE(DCF!$D$4,I8,I9,I10,#REF!,#REF!) -> 18.706312 | J7: =CHOOSE(DCF!$D$4,J8,J9,J10,#REF!,#REF!) -> 18.706312 | K7: =CHOOSE(DCF!$D$4,K8,K9,K10,#REF!,#REF!) -> 18.706312 | L7: =CHOOSE(DCF!$D$4,L8,L9,L10,#REF!,#REF!) -> 18.706312 | M7: =CHOOSE(DCF!$D$4,M8,M9,M10,#REF!,#REF!) -> 18.706312 | ... O7: =CHOOSE(DCF!$D$4,O8,O9,O10,#REF!,#REF!) -> 18.706312
B8: Base | E8: 1 | F8: ='Assumption 2 Documentation'!$F$5 -> 18.706312 | G8: ='Assumption 2 Documentation'!$F$5 -> 18.706312 | H8: ='Assumption 2 Documentation'!$F$5 -> 18.706312 | I8: ='Assumption 2 Documentation'!$F$5 -> 18.706312 | J8: ='Assumption 2 Documentation'!$F$5 -> 18.706312 | K8: ='Assumption 2 Documentation'!$F$5 -> 18.706312 | L8: ='Assumption 2 Documentation'!$F$5 -> 18.706312 | M8: ='Assumption 2 Documentation'!$F$5 -> 18.706312 | ... O8: ='Assumption 2 Documentation'!$F$5 -> 18.706312
B9: Upside | E9: 2 | F9: ='Assumption 2 Documentation'!$K$5 -> 18 | G9: 17.8 | H9: 17.5 | I9: 17.2 | J9: 17 | K9: 16.8 | L9: 16.7 | M9: 16.6 | N9: 16.5 | O9: 16.5
B10: Downside | E10: 3 | F10: 20 | G10: 20.5 | H10: 21 | I10: 21.5 | J10: 22 | K10: 22.3 | L10: 22.6 | M10: 22.8 | N10: 23 | O10: 23
B12: Days Inventory Held (DIH) | F12: =CHOOSE(DCF!$D$4,F13,F14,F15,#REF!,#REF!) -> 0 | G12: =CHOOSE(DCF!$D$4,G13,G14,G15,#REF!,#REF!) -> 0 | H12: =CHOOSE(DCF!$D$4,H13,H14,H15,#REF!,#REF!) -> 0 | I12: =CHOOSE(DCF!$D$4,I13,I14,I15,#REF!,#REF!) -> 0 | J12: =CHOOSE(DCF!$D$4,J13,J14,J15,#REF!,#REF!) -> 0 | K12: =CHOOSE(DCF!$D$4,K13,K14,K15,#REF!,#REF!) -> 0 | L12: =CHOOSE(DCF!$D$4,L13,L14,L15,#REF!,#REF!) -> 0 | M12: =CHOOSE(DCF!$D$4,M13,M14,M15,#REF!,#REF!) -> 0 | ... O12: =CHOOSE(DCF!$D$4,O13,O14,O15,#REF!,#REF!) -> 0
B13: Base | E13: 1 | F13: 0 | G13: =F13 -> 0 | H13: =G13 -> 0 | I13: =H13 -> 0 | J13: =I13 -> 0 | K13: =J13 -> 0 | L13: =K13 -> 0 | M13: =L13 -> 0 | N13: =M13 -> 0 | O13: =N13 -> 0
B14: Upside | E14: 2 | F14: 0 | G14: =F14 -> 0 | H14: =G14 -> 0 | I14: =H14 -> 0 | J14: =I14 -> 0 | K14: =J14 -> 0 | L14: =K14 -> 0 | M14: =L14 -> 0 | N14: =M14 -> 0 | O14: =N14 -> 0
B15: Downside | E15: 3 | F15: 0 | G15: =F15 -> 0 | H15: =G15 -> 0 | I15: =H15 -> 0 | J15: =I15 -> 0 | K15: =J15 -> 0 | L15: =K15 -> 0 | M15: =L15 -> 0 | N15: =M15 -> 0 | O15: =N15 -> 0
B17: Prepaid and Other Current Assets (% of sales) | F17: =CHOOSE(DCF!$D$4,F18,F19,F20,#REF!,#REF!) -> 0.01431 | G17: =CHOOSE(DCF!$D$4,G18,G19,G20,#REF!,#REF!) -> 0.01431 | H17: =CHOOSE(DCF!$D$4,H18,H19,H20,#REF!,#REF!) -> 0.01431 | I17: =CHOOSE(DCF!$D$4,I18,I19,I20,#REF!,#REF!) -> 0.01431 | J17: =CHOOSE(DCF!$D$4,J18,J19,J20,#REF!,#REF!) -> 0.01431 | K17: =CHOOSE(DCF!$D$4,K18,K19,K20,#REF!,#REF!) -> 0.01431 | L17: =CHOOSE(DCF!$D$4,L18,L19,L20,#REF!,#REF!) -> 0.01431 | M17: =CHOOSE(DCF!$D$4,M18,M19,M20,#REF!,#REF!) -> 0.01431 | ... O17: =CHOOSE(DCF!$D$4,O18,O19,O20,#REF!,#REF!) -> 0.01431
B18: Base | E18: 1 | F18: ='Assumption 2 Documentation'!$F$7 -> 0.01431 | G18: ='Assumption 2 Documentation'!$F$7 -> 0.01431 | H18: ='Assumption 2 Documentation'!$F$7 -> 0.01431 | I18: ='Assumption 2 Documentation'!$F$7 -> 0.01431 | J18: ='Assumption 2 Documentation'!$F$7 -> 0.01431 | K18: ='Assumption 2 Documentation'!$F$7 -> 0.01431 | L18: ='Assumption 2 Documentation'!$F$7 -> 0.01431 | M18: ='Assumption 2 Documentation'!$F$7 -> 0.01431 | ... O18: ='Assumption 2 Documentation'!$F$7 -> 0.01431
B19: Upside | E19: 2 | F19: 0.0135 | G19: 0.0132 | H19: 0.013 | I19: 0.0128 | J19: 0.0126 | K19: 0.012 | L19: 0.0122 | M19: 0.0121 | N19: 0.012 | O19: 0.012
B20: Downside | E20: 3 | F20: 0.015 | G20: 0.0155 | H20: 0.0158 | I20: 0.0162 | J20: 0.0165 | K20: 0.016 | L20: 0.0168 | M20: 0.0169 | N20: 0.017 | O20: 0.017
B22: Current Liabilities
B23: Days Payable Outstanding (DPO) | F23: =CHOOSE(DCF!$D$4,F24,F25,F26,#REF!,#REF!) -> 18.1 | G23: =CHOOSE(DCF!$D$4,G24,G25,G26,#REF!,#REF!) -> 18.1 | H23: =CHOOSE(DCF!$D$4,H24,H25,H26,#REF!,#REF!) -> 18.1 | I23: =CHOOSE(DCF!$D$4,I24,I25,I26,#REF!,#REF!) -> 18.1 | J23: =CHOOSE(DCF!$D$4,J24,J25,J26,#REF!,#REF!) -> 18.1 | K23: =CHOOSE(DCF!$D$4,K24,K25,K26,#REF!,#REF!) -> 18.1 | L23: =CHOOSE(DCF!$D$4,L24,L25,L26,#REF!,#REF!) -> 18.1 | M23: =CHOOSE(DCF!$D$4,M24,M25,M26,#REF!,#REF!) -> 18.1 | ... O23: =CHOOSE(DCF!$D$4,O24,O25,O26,#REF!,#REF!) -> 18.1
B24: Base | E24: 1 | F24: 18.1 | G24: =F24 -> 18.1 | H24: =G24 -> 18.1 | I24: =H24 -> 18.1 | J24: =I24 -> 18.1 | K24: =J24 -> 18.1 | L24: =K24 -> 18.1 | M24: =L24 -> 18.1 | N24: =M24 -> 18.1 | O24: =N24 -> 18.1
B25: Upside | E25: 2 | F25: 19 | G25: 19.5 | H25: 20 | I25: 20.5 | J25: 21 | K25: 21.3 | L25: 21.6 | M25: 21.8 | N25: 22 | O25: 22
B26: Downside | E26: 3 | F26: 17 | G26: 16.5 | H26: 16 | I26: 15.7 | J26: 15.5 | K26: 15.3 | L26: 15.2 | M26: 15.1 | N26: 15 | O26: 15
B28: Accrued Liabilities (% of sales) | F28: =CHOOSE(DCF!$D$4,F29,F30,F31,#REF!,#REF!) -> 0.064 | G28: =CHOOSE(DCF!$D$4,G29,G30,G31,#REF!,#REF!) -> 0.064 | H28: =CHOOSE(DCF!$D$4,H29,H30,H31,#REF!,#REF!) -> 0.064 | I28: =CHOOSE(DCF!$D$4,I29,I30,I31,#REF!,#REF!) -> 0.064 | J28: =CHOOSE(DCF!$D$4,J29,J30,J31,#REF!,#REF!) -> 0.064 | K28: =CHOOSE(DCF!$D$4,K29,K30,K31,#REF!,#REF!) -> 0.064 | L28: =CHOOSE(DCF!$D$4,L29,L30,L31,#REF!,#REF!) -> 0.064 | M28: =CHOOSE(DCF!$D$4,M29,M30,M31,#REF!,#REF!) -> 0.064 | ... O28: =CHOOSE(DCF!$D$4,O29,O30,O31,#REF!,#REF!) -> 0.064
B29: Base | E29: 1 | F29: 0.064 | G29: =F29 -> 0.064 | H29: =G29 -> 0.064 | I29: =H29 -> 0.064 | J29: =I29 -> 0.064 | K29: =J29 -> 0.064 | L29: =K29 -> 0.064 | M29: =L29 -> 0.064 | N29: =M29 -> 0.064 | O29: =N29 -> 0.064
B30: Upside | E30: 2 | F30: 0.066 | G30: 0.066 | H30: 0.067 | I30: 0.067 | J30: 0.067 | K30: 0.067 | L30: 0.068 | M30: 0.068 | N30: 0.068 | O30: 0.068
B31: Downside | E31: 3 | F31: 0.062 | G31: 0.061 | H31: 0.06 | I31: 0.06 | J31: 0.059 | K31: 0.059 | L31: 0.058 | M31: 0.058 | N31: 0.058 | O31: 0.058
B33: Other Current Liabilities (% of sales) | F33: =CHOOSE(DCF!$D$4,F34,F35,F36,#REF!,#REF!) -> 0.042 | G33: =CHOOSE(DCF!$D$4,G34,G35,G36,#REF!,#REF!) -> 0.042 | H33: =CHOOSE(DCF!$D$4,H34,H35,H36,#REF!,#REF!) -> 0.042 | I33: =CHOOSE(DCF!$D$4,I34,I35,I36,#REF!,#REF!) -> 0.042 | J33: =CHOOSE(DCF!$D$4,J34,J35,J36,#REF!,#REF!) -> 0.042 | K33: =CHOOSE(DCF!$D$4,K34,K35,K36,#REF!,#REF!) -> 0.042 | L33: =CHOOSE(DCF!$D$4,L34,L35,L36,#REF!,#REF!) -> 0.042 | M33: =CHOOSE(DCF!$D$4,M34,M35,M36,#REF!,#REF!) -> 0.042 | ... O33: =CHOOSE(DCF!$D$4,O34,O35,O36,#REF!,#REF!) -> 0.042
B34: Base | E34: 1 | F34: 0.042 | G34: =F34 -> 0.042 | H34: =G34 -> 0.042 | I34: =H34 -> 0.042 | J34: =I34 -> 0.042 | K34: =J34 -> 0.042 | L34: =K34 -> 0.042 | M34: =L34 -> 0.042 | N34: =M34 -> 0.042 | O34: =N34 -> 0.042
B35: Upside | E35: 2 | F35: 0.043 | G35: 0.043 | H35: 0.044 | I35: 0.044 | J35: 0.044 | K35: 0.044 | L35: 0.045 | M35: 0.045 | N35: 0.045 | O35: 0.045
B36: Downside | E36: 3 | F36: 0.04 | G36: 0.039 | H36: 0.039 | I36: 0.038 | J36: 0.038 | K36: 0.038 | L36: 0.037 | M36: 0.037 | N36: 0.037 | O36: 0.037

Sheet Assumption 2 Documentation
B3: A) Summary table | H3: C) Scenario table (linked to AS2 inputs)
B4: Metric | C4: FY2024 | D4: FY2023 | E4: FY2022 | F4: Avg | G4: Used for | H4: Metric | I4: Base 2025 | J4: Base 2034 | K4: Upside 2025 | L4: Upside 2034 | M4: Downside 2025 | N4: Downside 2034
B5: DSO | C5: 23.8295 | D5: 14.271893 | E5: 18.017543 | F5: =AVERAGE(C5:E5) -> 18.706312 | G5: AS2 Base 2025–2029 | H5: DSO | I5: =18.706 -> 18.706 | J5: 18.7 | K5: 18 | L5: 16.5 | M5: 20 | N5: 23
B6: DPO | C6: 21.18417 | D6: 16.90081 | E6: 16.23158 | F6: 18.11 | G6: AS2 Base 2025–2029 | H6: DPO | I6: =18.1 -> 18.1 | J6: 18.1 | K6: 19 | L6: 22 | M6: 17 | N6: 15
B7: Prepaid % | C7: 0.018194 | D7: 0.01292 | E7: 0.011826 | F7: 0.01431 | G7: AS2 Base 2025–2029 | H7: Prepaid | I7: =1.43% -> 0.0143 | J7: 0.0143 | K7: 0.014 | L7: 0.012 | M7: 0.015 | N7: 0.017
B8: Accrued % | C8: 0.057458 | D8: 0.061885 | E8: 0.071515 | F8: 0.06362 | G8: AS2 Base 2025–2029 | H8: Accrued | I8: =6.4% -> 0.064 | J8: =6.4% -> 0.064 | K8: 0.066 | L8: 0.068 | M8: 0.062 | N8: 0.058
B9: Other CL % | C9: 0.035159 | D9: 0.03697 | E9: 0.053919 | F9: 0.04202 | G9: AS2 Base 2025–2029 | H9: Other CL | I9: =4.2% -> 0.042 | J9: =4.2% -> 0.042 | K9: =4.3% -> 0.043 | L9: 0.045 | M9: 0.04 | N9: 0.037
B10: Notes
B11: FY2022–FY2024 averages computed from PitchBook financial statements (Planet Fitness, downloaded 17-Feb-2026).
B12: Formulas: DSO=AR/Revenue*365; DPO=AP/COGS*365; % items=BS line item/Revenue.
B14: B)Base case rationale (why Base is flat 2025-2034)
B15: Base (flat):
B16: We use the FY2022–FY2024 average for a proxy for steady-state working capital efficiency. Year-to-year fluctuations are mainly driven by timing effects, such as the timing of equipment sales, changes in other assets and prepaids, movements in accounts payable and accrued expenses, and shift in deferred revenue. This interpretation is consistent with the FY2024 10-K discussion of operating cash flow, which highlights changes in accounts receivable, other current assets (including prepaids), accounts payable and accrued expenses, and deferred revenue as key working capital drivers. (Planet Fitness, Inc., 2025, Form 10-K, p. 55). In External, broader market research suggests that DSO and DPO can change in a big scale over time, and that DSO in particular is an important driver of working capital levels. This supports our approach of setting a normalized Base case and then adjusting Upside and Downside scenarios around that assumptions.(PwC, 2024; The Hackett Group, 2024). | L16: D) Metric cards (narrative + key endpoints)
L17: Card 1 — Cash conversion (DSO/DPO)
B18: DSO
B19: Definition: | C19: (A/R ÷ Revenue) × 365 | L19: By 2034, the upside case assumes better cash conversion than the base case. DSO declines from 18.7 to 16.5 days and DPO increases from 18.1 to 22.0 days, reflecting faster collections and slightly more favorable supplier terms. In the downside case, cash conversion worsens: DSO rises to 23.0 days and DPO falls to 15.0 days. This results in slower collections and tighter payment timing under more stressed conditions. These directional assumptions are consistent with the company’s discussion in the 2024 Form 10-K, which highlights accounts receivable (including equipment sales timing) and accounts payable/accrued expenses (including equipment-related payables) as key working capital drivers (Planet Fitness, Inc., 2025, Form 10-K, p. 55). Historical baselines are anchored to FY2022–FY2024 averages calculated from PitchBook financial statements (PitchBook Data, Inc., 2026).
B20: Base (flat): | C20: Set to FY22–FY24 average (=18.7d) to represent steady-state collection efficiency; single-year DSO is timing-driven.
B21: 10-K linkage: | C21: Accounts receivable is influenced by equipment sales/placement activity; the 2024 working capital cash outflow was driven in part by an increase in accounts receivable due to higher equipment sales to existing franchisee-owned clubs. (Planet Fitness, Inc., 2025, Form 10-K, p. 55)
B22: Historical anchor | C22: FY22–FY24 averages computed from PitchBook financial statements (downloaded 17-Feb-2026). (PitchBook Data, Inc., 2026).
B23: Scenario logic / inputs: | C23: upside: gradual improvement to 16.5d by 2034 (scale + process efficiency) Downside: deterioration to 23.0d by 2034 (slower collections under stress). Collections efficiency (DSO) is a key driver of working capital and could worsen or improve depending on payment behavior and process discipline; we therefore flex DSO modestly around the Base in scenarios. (PwC, 2024).
B25: DPO
B26: Definition: | C26: A/P ÷ COGS) × 365 | L26: Metric | M26: Base (2034) | N26: Upside(2034) | O26: Downside (2034)
B27: Base (flat): | C27: FY22–24 avg = 18.1d | L27: DSO (days) | M27: =J5 -> 18.7 | N27: =L5 -> 16.5 | O27: =N5 -> 23
B28: 10-K linkage: | C28: The impact of working capital changes was partially offset by an increase in accounts payable and accrued expenses, mainly driven by payables associated with equipment orders. (Planet Fitness, Inc., 2025, Form 10-K, Operating activities discussion, p.55 | L28: DPO (days) | M28: =J6 -> 18.1 | N28: =L6 -> 22 | O28: =N6 -> 15
B29: Scenario logic / inputs: | C29: On the positive side, accounts payable payment timing is expected to gradually improve as equipment ordering activities expand. On the negative side, payment timing is expected to become tighter under stress conditions. (Planet Fitness, Inc., 2025, Form 10-K, p. 55)
B30: Historical anchor | C30: FY22–FY24 averages are calculated based on financial statements obtained from PitchBook (downloaded February 17, 2026) (PitchBook Data, Inc., 2026). Payables performance may tighten in more stressed environments and improve through proactive supplier management strategies. Accordingly, we adjust DPO in our scenarios, while keeping the changes relatively moderate (The Hackett Group, 2024). | L30: Card 2 —Balance-sheet ratios (% of sales)
B32: Prepaid & Other CA (% sales)
